Workbook

Sheet Расписание
A1: Дни недели | B1: понедельник | J1: вторник | R1: среда | Z1: четверг | AH1: пятница | AP1: Нагр. у. всего | AQ1: Нагр. у./класс
A2: ФИО учителя | B2: 1 | C2: 2 | D2: 3 | E2: 4 | F2: 5 | G2: 6 | H2: 7 | I2: 8 | J2: 1 | K2: 2 | L2: 3 | M2: 4 | N2: 5 | O2: 6 | P2: 7 | Q2: 8 | R2: 1 | S2: 2 | T2: 3 | U2: 4 | V2: 5 | W2: 6 | X2: 7 | Y2: 8 | Z2: 1 | AA2: 2 | AB2: 3 | AC2: 4 | AD2: 5 | AE2: 6 | AF2: 7 | AG2: 8 | AH2: 1 | AI2: 2 | AJ2: 3 | AK2: 4 | AL2: 5 | AM2: 6 | AN2: 7 | AO2: 8
A3: Стрибулева О.В. | C3: 5л | E3: 10е | J3: 10е | K3: 11е | L3: 5л | M3: 10г | N3: 5л | O3: 10г | R3: 11е | S3: 5л | U3: 10е | V3: 11е | W3: 5л | Z3: 11е | AA3: 11е | AB3: 11е | AC3: 5л | AD3: 10г | AH3: 10е | AI3: 10г | AJ3: 10г | AL3: 5л | AM3: 5л | AN3: 10е | AP3: =40-COUNTBLANK(B3:AO3) -> 24 | AQ3: =COUNTIF($C3:$AO3,$AS$3) -> 0 | AR3: =INDEX(#REF!,MATCH(Расписание!AS3,#REF!,0)) -> #REF! | AS3: 7о | AT3: Введите класс для поиска
A4: Бахвалова Н.Н. | C4: 5м | D4: 11г | E4: 11е | F4: 10е | G4: 5м | H4: 11г | J4: 11г | K4: 5м | L4: 10е | M4: 11е | N4: 11г | O4: 5м | R4: 10е | S4: 11е | T4: 10е | V4: 10е | W4: 5м | Z4: 5м | AA4: 11г | AB4: 11г | AC4: 10е | AD4: 10е | AH4: 11е | AI4: 11г | AJ4: 11е | AK4: 11г | AM4: 10е | AP4: =40-COUNTBLANK(B4:AO4) -> 27 | AQ4: =COUNTIF($C4:$AO4,$AS$3) -> 0 | AR4: =INDEX(#REF!,MATCH(Расписание!AS3,#REF!,0)) -> #REF! | AS4: =COUNTIF(Расписание!C3:AO45,AS3) -> 39 | AT4: Распределено часов в расписании
A5: Беспалова С.В. | C5: 5к | D5: 5л | E5: 5н | F5: 11д | G5: 11е | J5: 5л | K5: 11д | L5: 5к | M5: 5н | O5: 5л | P5: 11е | R5: 5л | S5: 5к | T5: 5л | U5: 5к | V5: 11д | W5: 11д | Z5: 11д | AA5: 5н | AB5: 5к | AD5: 5н | AH5: 5н | AJ5: 5н | AK5: 5к | AL5: 11е | AP5: =40-COUNTBLANK(B5:AO5) -> 25 | AQ5: =COUNTIF($C5:$AO5,$AS$3) -> 0 | AR5: =INDEX(#REF!,MATCH(Расписание!AS3,#REF!,0)) -> #REF! | AS5: =INDEX(#REF!,MATCH(Расписание!AS3,#REF!,0)) -> #REF! | AT5: Распределено часов в тарификации
A6: Рубцов В.С. | C6: 9м | D6: 5н | E6: 5к | G6: 9с | H6: 11е | J6: 5н | K6: 5л | L6: 11е | M6: 9к | N6: 9м | R6: 9с | S6: 9к | U6: 9л | V6: 5м | W6: 11е | X6: 10е | Z6: 10е | AA6: 5л | AB6: 9л | AE6: 11д | AH6: 10г | AI6: 10е | AK6: 5м | AL6: 5к | AM6: 11г | AP6: =40-COUNTBLANK(B6:AO6) -> 25 | AQ6: =COUNTIF($C6:$AO6,$AS$3) -> 0 | AR6: =INDEX(#REF!,MATCH(Расписание!AS3,#REF!,0)) -> #REF!
A7: Мальцева А.О. | C7: 11е | D7: 5к | H7: 10е | J7: 10г | K7: 10г | L7: 11д | M7: 11д | N7: 11е | O7: 10е | P7: 10г | Q7: 11г | R7: 11г | S7: 10г | T7: 11г | V7: 10г | W7: 11г | X7: 11д | Y7: 11д | Z7: 5к | AD7: 5к | AE7: 11г | AF7: 10е | AH7: 5к | AI7: 11д | AL7: 10е | AM7: 11е | AN7: 11е | AP7: =40-COUNTBLANK(B7:AO7) -> 27 | AQ7: =COUNTIF($C7:$AO7,$AS$3) -> 0 | AR7: =INDEX(#REF!,MATCH(Расписание!AS3,#REF!,0)) -> #REF! | AT7: Если номер класса красный, значит не совпадают часы в тарификафии и расписании
A8: Позднякова С.Л. | E8: 5л | F8: 5м | G8: 5л | H8: 10е | J8: 10г | K8: 10г | L8: 11д | M8: 11д | O8: 10е | P8: 10г | Q8: 11г | R8: 11г | S8: 10г | T8: 11г | U8: 5л | V8: 10г | W8: 11г | X8: 11д | Y8: 11д | AA8: 5м | AB8: 5л | AC8: 5м | AE8: 11г | AF8: 10е | AI8: 11д | AJ8: 5м | AK8: 5л | AL8: 10е | AP8: =40-COUNTBLANK(B8:AO8) -> 28 | AQ8: =COUNTIF($C8:$AO8,$AS$3) -> 0 | AR8: =INDEX(#REF!,MATCH(Расписание!AS3,#REF!,0)) -> #REF! | AT8: Если номер класса зелленый, значит все хорошо
A9: Гаршина Т.П. | Z9: 10г | AA9: 10г | AL9: 10г | AM9: 10г | AN9: 10г | AP9: =40-COUNTBLANK(B9:AO9) -> 5 | AQ9: =COUNTIF($C9:$AO9,$AS$3) -> 0 | AR9: =INDEX(#REF!,MATCH(Расписание!AS3,#REF!,0)) -> #REF!
A10: Карлина В.А. | C10: 10е | D10: 10е | E10: 11д | F10: 11е | G10: 10г | H10: 10г | L10: 11г | M10: 11г | N10: 10г | O10: 11д | P10: 10е | S10: 11д | T10: 11д | U10: 11г | V10: 11г | Z10: 11г | AA10: 10е | AB10: 10е | AC10: 11е | AD10: 11г | AE10: 11е | AI10: 11е | AJ10: 11г | AK10: 11е | AL10: 11г | AN10: 11г | AP10: =40-COUNTBLANK(B10:AO10) -> 26 | AQ10: =COUNTIF($C10:$AO10,$AS$3) -> 0 | AR10: =INDEX(#REF!,MATCH(Расписание!AS3,#REF!,0)) -> #REF!
A11: Луцкая А.В. | T11: 5н | AB11: 5н | AI11: 5н | AL11: 5н | AP11: =40-COUNTBLANK(B11:AO11) -> 4 | AQ11: =COUNTIF($C11:$AO11,$AS$3) -> 0 | AR11: =INDEX(#REF!,MATCH(Расписание!AS3,#REF!,0)) -> #REF!
A12: Бородулина Е.А. | T12: 5н | AB12: 5н | AI12: 5н | AL12: 5н | AP12: =40-COUNTBLANK(B12:AO12) -> 4 | AQ12: =COUNTIF($C12:$AO12,$AS$3) -> 0 | AR12: =INDEX(#REF!,MATCH(Расписание!AS3,#REF!,0)) -> #REF!
A13: Виноградова Е.А. | C13: 5н | D13: 5м | E13: 5м | F13: 5к | G13: 5к | K13: 5к | L13: 5н | M13: 5к | O13: 5н | R13: 5м | S13: 5м | U13: 5н | V13: 5н | Z13: 5н | AA13: 5к | AB13: 5м | AC13: 5к | AD13: 5м | AE13: 5н | AH13: 5м | AI13: 5м | AJ13: 5к | AK13: 5н | AM13: 5к | AP13: =40-COUNTBLANK(B13:AO13) -> 24 | AQ13: =COUNTIF($C13:$AO13,$AS$3) -> 0 | AR13: =INDEX(#REF!,MATCH(Расписание!AS3,#REF!,0)) -> #REF!
A14: Калинина Т.Н. | C14: 6о | D14: 6л | F14: 7н | G14: 8л | H14: 6н | J14: 7л | K14: 6о | M14: 7н | N14: 8к | O14: 8м | P14: 7о | R14: 8н | S14: 7л | T14: 7о | U14: 6л | V14: 6н | W14: 6м | Z14: 6л | AA14: 8л | AB14: 8н | AC14: 8м | AD14: 6м | AE14: 8к | AF14: 7л | AH14: 6м | AI14: 7о | AK14: 6н | AL14: 7н | AM14: 6о | AP14: =40-COUNTBLANK(B14:AO14) -> 29 | AQ14: =COUNTIF($C14:$AO14,$AS$3) -> 3 | AR14: =INDEX(#REF!,MATCH(Расписание!AS3,#REF!,0)) -> #REF!
A15: Колобанова И.В. | C15: 11е | D15: 5к | E15: 5л | F15: 5м | G15: 5л | J15: 9м | K15: 9к | L15: 9л | M15: 9с | N15: 11е | O15: 9к | P15: 9л | R15: 9м | S15: 9м | T15: 9к | U15: 5л | V15: 9с | W15: 9л | X15: 9с | Z15: 5к | AA15: 5м | AB15: 5л | AC15: 5м | AD15: 5к | AH15: 5к | AJ15: 5м | AK15: 5л | AM15: 11е | AN15: 11е | AP15: =40-COUNTBLANK(B15:AO15) -> 29 | AQ15: =COUNTIF($C15:$AO15,$AS$3) -> 0 | AR15: =INDEX(#REF!,MATCH(Расписание!AS3,#REF!,0)) -> #REF!
A16: Баринов Е.И. | F16: 5н | G16: 5н | J16: 5к | N16: 5м | O16: 5к | R16: 6л | S16: 6м | T16: 6о | U16: 6н | V16: 7л | W16: 7н | X16: 7о | Z16: 5л | AE16: 5л | AM16: 5м | AP16: =40-COUNTBLANK(B16:AO16) -> 15 | AQ16: =COUNTIF($C16:$AO16,$AS$3) -> 1 | AR16: =INDEX(#REF!,MATCH(Расписание!AS3,#REF!,0)) -> #REF!
A17: Лукьянова Л.К. | C17: 6м | D17: 6м | E17: 6л | F17: 6л | N17: 9с | O17: 9м | P17: 9к | R17: 11д | S17: 10е | T17: 11е | U17: 11е | V17: 9л | W17: 10г | X17: 11г | Z17: 8м | AA17: 7л | AB17: 7о | AC17: 7н | AD17: 8л | AE17: 8н | AH17: 8м | AI17: 8н | AJ17: 8к | AK17: 8к | AL17: 8л | AP17: =40-COUNTBLANK(B17:AO17) -> 25 | AQ17: =COUNTIF($C17:$AO17,$AS$3) -> 1 | AR17: =INDEX(#REF!,MATCH(Расписание!AS3,#REF!,0)) -> #REF!
A18: Соколова С.А. | G18: 6о | J18: 6н | K18: 6н | L18: 6о | N18: 9с | O18: 9м | P18: 9к | R18: 11д | S18: 10е | T18: 11е | U18: 11е | V18: 9л | W18: 10г | X18: 11г | Z18: 8м | AA18: 7л | AB18: 7о | AC18: 7н | AD18: 8л | AE18: 8н | AH18: 8м | AI18: 8н | AJ18: 8к | AK18: 8к | AL18: 8л | AP18: =40-COUNTBLANK(B18:AO18) -> 25 | AQ18: =COUNTIF($C18:$AO18,$AS$3) -> 1 | AR18: =INDEX(#REF!,MATCH(Расписание!AS3,#REF!,0)) -> #REF!
A19: Буданова О.В. | C19: 6м | D19: 6м | E19: 6л | F19: 6л | G19: 6о | J19: 6н | K19: 6н | L19: 6о | R19: 5н | S19: 5н | T19: 5м | U19: 5м | V19: 5к | W19: 5к | Z19: 7о | AA19: 7о | AB19: 7л | AC19: 7л | AD19: 7н | AE19: 7н | AH19: 5л | AI19: 5л | AP19: =40-COUNTBLANK(B19:AO19) -> 22 | AQ19: =COUNTIF($C19:$AO19,$AS$3) -> 2 | AR19: =INDEX(#REF!,MATCH(Расписание!AS3,#REF!,0)) -> #REF!
A20: Пушин К.В. | D20: 11е | E20: 10г | F20: 11г | G20: 10е | J20: 9л | K20: 9с | M20: 9м | N20: 11д | R20: 5н | S20: 5н | T20: 5м | U20: 5м | V20: 5к | W20: 5к | X20: 9к | Z20: 7о | AA20: 7о | AB20: 7л | AC20: 7л | AD20: 7н | AE20: 7н | AH20: 5л | AI20: 5л | AJ20: 9м | AK20: 9с | AL20: 9к | AM20: 9л | AP20: =40-COUNTBLANK(B20:AO20) -> 27 | AQ20: =COUNTIF($C20:$AO20,$AS$3) -> 2 | AR20: =INDEX(#REF!,MATCH(Расписание!AS3,#REF!,0)) -> #REF!
A21: Киреева Г.В. | C21: 11д | D21: 9м | E21: 9л | F21: 9м | G21: 9л | H21: 9к | J21: 11е | K21: 10е | L21: 10г | M21: 10е | O21: 11г | P21: 9с | R21: 8м | T21: 8л | V21: 8к | W21: 8н | Z21: 9л | AA21: 9с | AB21: 9м | AC21: 9к | AD21: 9с | AE21: 9к | AF21: 11е | AH21: 8л | AI21: 8к | AK21: 8м | AL21: 8н | AP21: =40-COUNTBLANK(B21:AO21) -> 27 | AQ21: =COUNTIF($C21:$AO21,$AS$3) -> 0 | AR21: =INDEX(#REF!,MATCH(Расписание!AS3,#REF!,0)) -> #REF!
A22: Алферова И.Ю. | C22: 9л | D22: 10г | E22: 9с | F22: 9к | G22: 11г | J22: 8н | K22: 8к | L22: 8н | M22: 8л | N22: 8м | O22: 8к | S22: 9л | T22: 9м | U22: 9с | W22: 10е | X22: 11е | Z22: 8н | AA22: 8к | AB22: 8м | AC22: 8л | AD22: 8м | AE22: 8л | AH22: 9м | AJ22: 10е | AK22: 9к | AL22: 11д | AP22: =40-COUNTBLANK(B22:AO22) -> 26 | AQ22: =COUNTIF($C22:$AO22,$AS$3) -> 0 | AR22: =INDEX(#REF!,MATCH(Расписание!AS3,#REF!,0)) -> #REF!
A23: Малышев А.А. | C23: 11г | D23: 9л | E23: 11г | F23: 9с | G23: 9м | H23: 11д | J23: 11д | K23: 11г | L23: 9с | M23: 9л | N23: 9л | O23: 9с | P23: 11д | R23: 9л | U23: 9м | V23: 9м | W23: 9с | Z23: 9с | AA23: 11д | AC23: 11г | AD23: 11д | AE23: 9л | AF23: 11д | AH23: 11г | AI23: 9с | AJ23: 11д | AK23: 11д | AL23: 9л | AM23: 11д | AP23: =40-COUNTBLANK(B23:AO23) -> 29 | AQ23: =COUNTIF($C23:$AO23,$AS$3) -> 0 | AR23: =INDEX(#REF!,MATCH(Расписание!AS3,#REF!,0)) -> #REF!
A24: Бойкова Е.А. | C24: 10г | D24: 9с | E24: 9к | F24: 10г | G24: 9к | H24: 9л | J24: 9с | K24: 9л | L24: 9к | N24: 9к | O24: 9л | R24: 10г | S24: 9с | T24: 9л | U24: 9к | V24: 9к | X24: 10г | AB24: 10г | AC24: 10г | AD24: 9л | AE24: 10г | AF24: 9с | AH24: 9л | AI24: 9л | AJ24: 9к | AK24: 10г | AL24: 9с | AM24: 9с | AN24: 9с | AP24: =40-COUNTBLANK(B24:AO24) -> 29 | AQ24: =COUNTIF($C24:$AO24,$AS$3) -> 0 | AR24: =INDEX(#REF!,MATCH(Расписание!AS3,#REF!,0)) -> #REF!
A25: Кирпач И.Ю. | J25: 5м | K25: 5н | L25: 5м | N25: 10е | O25: 11е | P25: 11г | R25: 5к | T25: 10г | U25: 10г | V25: 5л | W25: 5н | AH25: 11д | AI25: 5к | AJ25: 5л | AK25: 10е | AP25: =40-COUNTBLANK(B25:AO25) -> 15 | AQ25: =COUNTIF($C25:$AO25,$AS$3) -> 0 | AR25: =INDEX(#REF!,MATCH(Расписание!AS3,#REF!,0)) -> #REF!
A26: Пименова П.К. | D26: 6о | E26: 8к | F26: 8л | H26: 6м | I26: 8н | J26: 7о | K26: 8н | L26: 7л | M26: 8к | P26: 8м | R26: 9к | S26: 11г | T26: 9с | U26: 11д | W26: 9м | X26: 9л | Z26: 9м | AA26: 9к | AC26: 9с | AD26: 11е | AF26: 9л | AI26: 6н | AJ26: 6л | AK26: 8л | AL26: 8м | AM26: 7н | AP26: =40-COUNTBLANK(B26:AO26) -> 26 | AQ26: =COUNTIF($C26:$AO26,$AS$3) -> 1 | AR26: =INDEX(#REF!,MATCH(Расписание!AS3,#REF!,0)) -> #REF!
A27: Шипилова.М.Ю. | C27: 8н | D27: 8к | E27: 8м | F27: 8к | G27: 6л | J27: 6л | K27: 8л | L27: 6л | M27: 6л | N27: 8н | R27: 8л | S27: 8к | T27: 6л | U27: 8н | V27: 6л | Z27: 8л | AA27: 8м | AB27: 8л | AC27: 6л | AD27: 6л | AH27: 8н | AI27: 8м | AJ27: 8л | AK27: 8н | AL27: 6л | AP27: =40-COUNTBLANK(B27:AO27) -> 25 | AQ27: =COUNTIF($C27:$AO27,$AS$3) -> 0 | AR27: =INDEX(#REF!,MATCH(Расписание!AS3,#REF!,0)) -> #REF!
A28: Баранова А.C. | C28: 6л | D28: 7о | E28: 8н | G28: 8н | H28: 6л | K28: 7л | L28: 8л | M28: 6о | O28: 6о | U28: 7л | V28: 8л | W28: 6о | X28: 8л | Z28: 7л | AA28: 6л | AB28: 6л | AC28: 7о | AD28: 6о | AE28: 7о | AF28: 8н | AI28: 7л | AJ28: 8н | AL28: 6о | AM28: 7о | AN28: 8л | AP28: =40-COUNTBLANK(B28:AO28) -> 25 | AQ28: =COUNTIF($C28:$AO28,$AS$3) -> 4 | AR28: =INDEX(#REF!,MATCH(Расписание!AS3,#REF!,0)) -> #REF!
A29: Никулина М.Е. | C29: 9с | D29: 11д | F29: 9л | G29: 11д | H29: 9м | K29: 9м | L29: 9м | M29: 5м | N29: 5н | S29: 8н | T29: 8м | U29: 8к | W29: 8л | Z29: 9к | AA29: 9л | AB29: 9с | AC29: 5н | AD29: 9к | AE29: 5м | AH29: 9с | AI29: 9к | AJ29: 9л | AL29: 5м | AM29: 5н | AP29: =40-COUNTBLANK(B29:AO29) -> 24 | AQ29: =COUNTIF($C29:$AO29,$AS$3) -> 0 | AR29: =INDEX(#REF!,MATCH(Расписание!AS3,#REF!,0)) -> #REF!
A30: Зонова А.В. | D30: 7л | E30: 7о | G30: 7н | AB30: 7н | AD30: 7о | AE30: 7л | AP30: =40-COUNTBLANK(B30:AO30) -> 6 | AQ30: =COUNTIF($C30:$AO30,$AS$3) -> 2 | AR30: =INDEX(#REF!,MATCH(Расписание!AS3,#REF!,0)) -> #REF!
A31: Файнер О.В. | C31: 9к | D31: 9к | E31: 9м | G31: 6н | H31: 6о | J31: 9к | L31: 6н | M31: 6н | N31: 6о | O31: 6н | R31: 6н | S31: 6о | T31: 6н | U31: 6о | W31: 9к | X31: 9м | Z31: 6н | AA31: 6о | AB31: 6н | AC31: 6о | AD31: 6н | AE31: 6о | AH31: 6о | AI31: 6о | AK31: 9м | AM31: 9к | AN31: 9к | AP31: =40-COUNTBLANK(B31:AO31) -> 27 | AQ31: =COUNTIF($C31:$AO31,$AS$3) -> 0 | AR31: =INDEX(#REF!,MATCH(Расписание!AS3,#REF!,0)) -> #REF!
A32: Попова А.С. | C32: 8м | D32: 8н | E32: 7л | F32: 6о | G32: 7о | H32: 8л | J32: 8к | K32: 7н | L32: 7о | M32: 7л | N32: 6л | O32: 6м | P32: 8н | R32: 8к | S32: 6н | U32: 8л | V32: 7н | W32: 8м | AA32: 9м | AB32: 9к | AC32: 9л | AE32: 9с | AH32: 9к | AI32: 9м | AJ32: 9с | AK32: 9л | AP32: =40-COUNTBLANK(B32:AO32) -> 26 | AQ32: =COUNTIF($C32:$AO32,$AS$3) -> 2 | AR32: =INDEX(#REF!,MATCH(Расписание!AS3,#REF!,0)) -> #REF!
A33: Пронкина О.Н. | C33: 7л | E33: 7н | F33: 7о | H33: 8м | J33: 8м | K33: 6м | L33: 7н | M33: 6м | N33: 7н | O33: 7о | P33: 7л | R33: 6м | S33: 7о | T33: 7н | U33: 7н | V33: 6м | W33: 7о | X33: 7л | Z33: 6м | AA33: 7н | AB33: 6м | AD33: 7л | AE33: 6м | AF33: 8к | AH33: 7о | AI33: 6м | AJ33: 7л | AK33: 7л | AL33: 6м | AM33: 8к | AN33: 7о | AP33: =40-COUNTBLANK(B33:AO33) -> 31 | AQ33: =COUNTIF($C33:$AO33,$AS$3) -> 6 | AR33: =INDEX(#REF!,MATCH(Расписание!AS3,#REF!,0)) -> #REF!
A34: Алимова Е.М. | C34: 8к | D34: 7о | E34: 8н | G34: 8н | H34: 8к | J34: 9м | K34: 9к | L34: 9л | M34: 9с | O34: 9к | P34: 9л | R34: 9м | S34: 9м | T34: 9к | V34: 9с | W34: 9л | X34: 9с | Z34: 8к | AB34: 8к | AC34: 7о | AE34: 7о | AF34: 8н | AJ34: 8н | AM34: 7о | AP34: =40-COUNTBLANK(B34:AO34) -> 24 | AQ34: =COUNTIF($C34:$AO34,$AS$3) -> 4 | AR34: =INDEX(#REF!,MATCH(Расписание!AS3,#REF!,0)) -> #REF!
A35: Беспроскурнова К.В. | C35: 8л | D35: 8л | E35: 8л | F35: 8н | G35: 8к | H35: 8н | J35: 8л | K35: 7о | M35: 8н | N35: 7о | O35: 8н | P35: 8к | R35: 7о | S35: 8л | T35: 8н | U35: 7о | V35: 7о | W35: 8к | X35: 8н | AA35: 8н | AC35: 8к | AH35: 8к | AI35: 8л | AJ35: 7о | AK35: 7о | AL35: 8к | AM35: 8л | AN35: 8к | AP35: =40-COUNTBLANK(B35:AO35) -> 28 | AQ35: =COUNTIF($C35:$AO35,$AS$3) -> 7 | AR35: =INDEX(#REF!,MATCH(Расписание!AS3,#REF!,0)) -> #REF!
A36: Липская Т.Ю. | C36: 8к | D36: 8м | E36: 6н | F36: 6м | G36: 8м | H36: 8к | L36: 8л | M36: 6о | N36: 6м | O36: 6о | P36: 7н | R36: 7н | S36: 8м | T36: 6м | V36: 8л | W36: 6о | X36: 8л | Z36: 8к | AB36: 8к | AC36: 6н | AD36: 6о | AE36: 6н | AF36: 7н | AH36: 7н | AJ36: 8м | AK36: 6м | AL36: 6о | AM36: 6н | AN36: 8л | AP36: =40-COUNTBLANK(B36:AO36) -> 29 | AQ36: =COUNTIF($C36:$AO36,$AS$3) -> 0 | AR36: =INDEX(#REF!,MATCH(Расписание!AS3,#REF!,0)) -> #REF!
A37: Остащенко Н.В. | C37: 7н | D37: 7н | F37: 8м | G37: 7л | H37: 7л | J37: 7н | K37: 8м | L37: 8м | M37: 8м | N37: 7л | O37: 7л | R37: 7л | S37: 7н | T37: 7л | U37: 8м | V37: 8м | W37: 7л | X37: 8м | Z37: 7н | AC37: 9м | AD37: 9м | AE37: 9м | AF37: 9м | AI37: 7н | AJ37: 7н | AL37: 9м | AM37: 9м | AN37: 9м | AP37: =40-COUNTBLANK(B37:AO37) -> 28 | AQ37: =COUNTIF($C37:$AO37,$AS$3) -> 0 | AR37: =INDEX(#REF!,MATCH(Расписание!AS3,#REF!,0)) -> #REF!
A38: Исайкина О.М. | C38: 6л | D38: 8м | E38: 6н | F38: 6м | G38: 8м | H38: 6л | K38: 7л | N38: 6м | P38: 7н | R38: 7н | S38: 8м | T38: 6м | U38: 7л | Z38: 7л | AA38: 6л | AB38: 6л | AC38: 6н | AE38: 6н | AF38: 7н | AH38: 7н | AI38: 7л | AJ38: 8м | AK38: 6м | AM38: 6н | AP38: =40-COUNTBLANK(B38:AO38) -> 24 | AQ38: =COUNTIF($C38:$AO38,$AS$3) -> 0 | AR38: =INDEX(#REF!,MATCH(Расписание!AS3,#REF!,0)) -> #REF!
A39: Сидоров С.А. | C39: 6н | E39: 6о | F39: 6н | G39: 6м | I39: 8л | J39: 6м | K39: 6л | L39: 6м | N39: 6н | O39: 6л | R39: 6о | S39: 6л | T39: 8к | U39: 6м | V39: 6о | W39: 6н | Z39: 6о | AA39: 6м | AC39: 6м | AD39: 8н | AE39: 6л | AF39: 8м | AH39: 6н | AJ39: 6о | AK39: 6л | AL39: 6н | AM39: 6л | AP39: =40-COUNTBLANK(B39:AO39) -> 27 | AQ39: =COUNTIF($C39:$AO39,$AS$3) -> 0 | AR39: =INDEX(#REF!,MATCH(Расписание!AS3,#REF!,0)) -> #REF!
A40: Шашеро А.В. | C40: 7о | D40: 6н | E40: 6м | F40: 7л | J40: 6о | L40: 8к | M40: 7о | N40: 8л | O40: 7н | V40: 8н | W40: 6л | AA40: 6н | AB40: 6о | AC40: 8н | AD40: 8к | AE40: 8м | AF40: 8л | AH40: 6л | AJ40: 6м | AK40: 7н | AL40: 7л | AM40: 8м | AP40: =40-COUNTBLANK(B40:AO40) -> 22 | AQ40: =COUNTIF($C40:$AO40,$AS$3) -> 2 | AR40: =INDEX(#REF!,MATCH(Расписание!AS3,#REF!,0)) -> #REF!
...

Sheet Кабинеты
A1: ФИО | B1: кабинеты корпуса 1115 | C1: вместимость | D1: кабинеты корпуса 1128 | E1: вместимость
A2: Алимова Е.М. | B2: 202 | C2: 30 | D2: 311а | E2: 17
A3: Алферова И.Ю. | B3: 203 | C3: 30 | D3: 320 | E3: 30
A4: Баранова А.C. | B4: 211 | C4: 30
A5: Баринов Е.И. | B5: 118 | C5: 30 | D5: 107 | E5: 30
A6: Бахвалова Н.Н. | B6: - | C6: - | D6: 216 | E6: 30
A7: Беспалова С.В. | B7: - | C7: - | D7: 215 | E7: 30
A8: Беспроскурнова К.В. | B8: 214 | C8: 30 | D8: - | E8: -
A9: Бойкова Е.А. | B9: - | C9: - | D9: 317 | E9: 30
A10: Бородулина Е.А. | B10: - | C10: - | D10: 211а | E10: 17
A11: Буданова О.В. | B11: 119 | C11: 30 | D11: 302 | E11: 30
A12: Шипилова.М.Ю. | B12: 101 | C12: 30
A13: Виноградова Е.А. | B13: - | C13: - | D13: 316 | E13: 30
A14: Гаршина Т.П. | B14: - | C14: - | D14: 308 | E14: 30
A15: Генералова О.П. | B15: - | C15: - | D15: 205 | E15: 30
A16: ДТ | B16: - | C16: - | D16: 314 | E16: 30
A17: Зонова А.В. | B17: 209 | C17: 30 | D17: - | E17: -
A18: Исайкина О.М. | B18: 205 | C18: 17 | D18: - | E18: -
A19: Калинина Т.Н. | B19: 210 | C19: 30 | D19: - | E19: -
A20: Карлина В.А. | B20: - | C20: - | D20: 304 | E20: 30
A21: Киреева Г.В. | B21: 304 | C21: 30 | D21: 305 | E21: 30
A22: Кирпач И.Ю. | B22: - | C22: - | D22: 220 | E22: 30
A23: Колобанова И.В. | B23: - | C23: - | D23: 311а | E23: 17
A24: Липская Т.Ю. | B24: 212 | C24: 17 | D24: - | E24: -
A25: Лукьянова Л.К. | B25: 301а | C25: 17 | D25: 318а | E25: 17
A26: Луцкая А.В. | B26: - | C26: - | D26: 211б | E26: 17
A27: Малышев А.А. | B27: - | C27: - | D27: 102 | E27: 30
A28: Мальцева А.О. | B28: - | C28: - | D28: 310 | E28: 30
A29: Никулина М.Е. | B29: 208 | C29: 30 | D29: 106 | E29: 30
A30: Остащенко Н.В. | B30: 302 | C30: 30 | D30: 221 | E30: 30
A31: Пименова П.К. | B31: 204 | C31: 30 | D31: 220-308 | E31: 30
A32: Позднякова С.Л. | B32: - | C32: - | D32: 312 | E32: 30
A33: Попова А.С. | B33: 315 | C33: 30 | D33: 309 | E33: 30
A34: Пронкина О.Н. | B34: 106 | C34: 30 | D34: - | E34: -
A35: Пушин К.В. | B35: 309 | C35: 30 | D35: 218 | E35: 30
A36: Рубцов В.С. | B36: - | C36: - | D36: сп/з | E36: -
A37: Сидоров С.А. | B37: 213 | C37: 30 | D37: - | E37: -
A38: Смирнова В.В. | B38: - | C38: - | D38: 314 | E38: 30
A39: Соколова С.А. | B39: 201А | C39: 17 | D39: 318б | E39: 17
A40: Стрибулева О.В. | B40: - | C40: - | D40: 315 | E40: 30
...

Sheet Тарификация
A1: ФИО | B1: Предмет | C1: 5к | D1: 5л | E1: 5м | F1: 5н | G1: 6л | H1: 6м | I1: 6н | J1: 6о | K1: 7л | L1: 7н | M1: 7о | N1: 8к | O1: 8л | P1: 8м | Q1: 8н | R1: 9к | S1: 9л | T1: 9м | U1: 9с | V1: 10г | W1: 10е | X1: 11г | Y1: 11д | Z1: 11е | AA1: Деление по группам | AB1: Исключения | AC1: Урок сдвоенный
A2: Алимова Е.М. | B2: англ. язык | M2: 4 | N2: 4 | Q2: 4 | R2: 3 | S2: 3 | T2: 3 | U2: 3 | AA2: Да | AB2: -
A3: Алферова И.Ю. | B3: химия | N3: 3 | O3: 3 | P3: 3 | Q3: 3 | R3: 2 | S3: 2 | T3: 2 | U3: 2 | V3: 1 | W3: 2 | X3: 1 | Y3: 1 | Z3: 1 | AA3: Нет | AB3: -
A4: Баранова А.C. | B4: англ. язык | G4: 3 | J4: 3 | K4: 3 | M4: 3 | O4: 3 | Q4: 3 | AA4: Да | AB4: -
A5: Баранова А.C. | B5: практикум по англ. | G5: 1 | J5: 2 | K5: 1 | M5: 1 | O5: 1 | Q5: 1 | AA5: Да | AB5: -
A6: Баринов Е.И. | B6: ИЗО | C6: 1 | D6: 1 | E6: 1 | F6: 1 | AA6: Нет | AB6: -
A7: Баринов Е.И. | B7: музыка | C7: 1 | D7: 1 | E7: 1 | F7: 1 | G7: 1 | H7: 1 | I7: 1 | J7: 1 | K7: 1 | L7: 1 | M7: 1 | AA7: Нет | AB7: -
A8: Бахвалова Н.Н. | B8: математика | E8: 6 | W8: 8 | X8: 8 | Z8: 5 | AA8: Нет | AB8: -
A9: Беспалова С.В. | B9: математика | C9: 6 | D9: 5 | F9: 6 | Y9: 5 | Z9: 3 | AA9: Нет | AB9: -
A10: Беспроскурнова К.В. | B10: математика | M10: 7 | N10: 7 | O10: 7 | Q10: 7 | AA10: Нет | AB10: -
A11: Бойкова Е.А. | B11: математика | R11: 7 | S11: 7 | U11: 7 | V11: 8 | AA11: Нет | AB11: -
A12: Бородулина Е.А. | B12: англ. язык | F12: 4 | AA12: Да | AB12: -
A13: Буданова О.В. | B13: Труд(технология) | C13: 2 | D13: 2 | E13: 2 | F13: 2 | G13: 2 | H13: 2 | I13: 2 | J13: 2 | K13: 2 | L13: 2 | M13: 2 | AA13: Да | AB13: -
A14: Шипилова.М.Ю. | B14: филология | G14: 9 | N14: 3 | O14: 5 | P14: 3 | Q14: 5 | AA14: Нет | AB14: -
A15: Виноградова Е.А. | B15: филология | C15: 8 | E15: 8 | F15: 8 | AA15: Нет | AB15: -
A16: Гаршина Т.П. | B16: обществознание | V16: 5 | AA16: Нет | AB16: -
A17: Генералова О.П. | B17: история | C17: 3 | D17: 3 | AA17: Нет | AB17: -
A18: ДТ | B18: - | Y18: 2 | AA18: Нет | AB18: -
A19: Зонова А.В. | B19: физика | K19: 2 | L19: 2 | M19: 2 | AA19: Нет | AB19: -
A20: Исайкина О.М. | B20: англ. язык | G20: 4 | H20: 4 | I20: 4 | K20: 4 | L20: 4 | P20: 4 | AA20: Да | AB20: -
A21: Калинина Т.Н. | B21: история | G21: 3 | H21: 3 | I21: 3 | J21: 3 | K21: 3 | L21: 3 | M21: 3 | N21: 2 | O21: 2 | P21: 2 | Q21: 2 | AA21: Нет | AB21: -
A22: Карлина В.А. | B22: история | V22: 2 | W22: 2 | X22: 2 | Z22: 2 | AA22: Нет | AB22: -
A23: Карлина В.А. | B23: общество | V23: 1 | W23: 3 | X23: 7 | Y23: 4 | Z23: 3 | AA23: Нет | AB23: -
A24: Киреева Г.В. | B24: физика | N24: 2 | O24: 2 | P24: 2 | Q24: 2 | R24: 3 | S24: 3 | T24: 3 | U24: 3 | V24: 1 | W24: 2 | X24: 1 | Y24: 1 | Z24: 2 | AA24: Нет | AB24: -
A25: Кирпач И.Ю. | B25: биология | C25: 1 | D25: 1 | E25: 1 | F25: 1 | V25: 1 | W25: 1 | AA25: Нет | AB25: -
A26: Кирпач И.Ю. | B26: география | C26: 1 | D26: 1 | E26: 1 | F26: 1 | V26: 1 | W26: 1 | X26: 1 | Y26: 1 | Z26: 1 | AA26: Нет | AB26: -
A27: Колобанова И.В. | B27: англ. язык | C27: 4 | D27: 5 | E27: 4 | R27: 3 | S27: 3 | T27: 3 | U27: 3 | Z27: 4 | AA27: Да | AB27: -
A28: Липская Т.Ю. | B28: практикум по англ. | H28: 1 | I28: 1 | J28: 2 | L28: 1 | N28: 1 | O28: 1 | P28: 1 | AA28: Да | AB28: -
A29: Липская Т.Ю. | B29: англ. Язык | H29: 3 | I29: 3 | J29: 3 | L29: 3 | N29: 3 | O29: 3 | P29: 3 | AA29: Да | AB29: -
A30: Лукьянова Л.К. | B30: информатика | K30: 1 | L30: 1 | M30: 1 | N30: 1 | O30: 1 | P30: 1 | Q30: 1 | R30: 1 | S30: 1 | T30: 1 | U30: 1 | V30: 1 | W30: 1 | X30: 1 | Y30: 1 | Z30: 2 | AA30: Да | AB30: -
A31: Лукьянова Л.К. | B31: Труд(технология ) | G31: 2 | H31: 2 | N31: 1 | O31: 1 | P31: 1 | Q31: 1 | AA31: Нет | AB31: -
A32: Луцкая А.В. | B32: практикум по англ. | F32: 4 | AA32: Да | AB32: -
A33: Малышев А.А. | B33: филология | S33: 6 | T33: 3 | U33: 6 | X33: 5 | Y33: 9 | AA33: Нет | AB33: -
A34: Мальцева А.О. | B34: англ. язык | C34: 4 | V34: 5 | W34: 4 | X34: 5 | Y34: 5 | Z34: 4 | AA34: Да | AB34: -
A35: Никулина М.Е. | B35: общество | N35: 1 | O35: 1 | P35: 1 | Q35: 1 | R35: 1 | S35: 1 | T35: 1 | U35: 1 | AA35: Нет | AB35: -
A36: Никулина М.Е. | B36: история | E36: 3 | F36: 3 | R36: 2 | S36: 2 | T36: 2 | U36: 2 | Y36: 2 | AA36: Нет | AB36: -
A37: Остащенко Н.В. | B37: математика | K37: 7 | L37: 7 | P37: 7 | T37: 7 | AA37: Нет | AB37: -
A38: Пименова П.К. | B38: биология | G38: 1 | H38: 1 | I38: 1 | J38: 1 | K38: 1 | L38: 1 | M38: 1 | N38: 2 | O38: 2 | P38: 2 | Q38: 2 | R38: 2 | S38: 2 | T38: 2 | U38: 2 | X38: 1 | Y38: 1 | Z38: 1 | AA38: Нет | AB38: -
A39: Позднякова С.Л. | B39: англ. язык | D39: 5 | E39: 4 | V39: 5 | W39: 4 | X39: 5 | Y39: 5 | AA39: Да | AB39: -
A40: Попова А.С. | B40: география | G40: 1 | H40: 1 | I40: 1 | J40: 1 | K40: 2 | L40: 2 | M40: 2 | N40: 2 | O40: 2 | P40: 2 | Q40: 2 | R40: 2 | S40: 2 | T40: 2 | U40: 2 | AA40: Нет | AB40: -
...

Sheet База данных
A1: ФИО учителей | B1: Классы
A2: Алимова Е.М. | B2: 5к
A3: Шипилова.М.Ю. | B3: 5л
A4: Алферова И.Ю. | B4: 5м
A5: Баранова А.C. | B5: 5н
A6: Баринов Е.И. | B6: 6л
A7: Бахвалова Н.Н. | B7: 6м
A8: Беспалова С.В. | B8: 6н
A9: Беспроскурнова К.В. | B9: 6о
A10: Бойкова Е.А. | B10: 7л
A11: Буданова О.В. | B11: 7н
A12: Рубцов В.С. | B12: 7о
... A25: Малышев А.А. | B25: 11е
A26: Мальцева А.О.
A27: Файнер О.В.
A28: Пронкина О.Н.
A29: Бородулина Е.А.
A30: Гаршина Т.П.
A31: Лазукина А.Н.
A32: Никулина М.Е.
A33: Остащенко Н.В.
A34: Позднякова С.Л.
A35: Попова А.С.
A36: Пушин К.В.
A37: Сидоров С.А.
... A44: Шашеро А.В.

Sheet Корпуса
A1: - | B1: 912 | C1: 913 | D1: 1115
A2: 912 | B2: - | C2: 0 | D2: 1
A3: 913 | B3: 0 | C3: - | D3: 1
A4: 1115 | B4: 1 | C4: 1 | D4: -
